<robot name = "robot">
    <link name="0">
        <inertial>
            <origin xyz="0 0 5" rpy="0 0 0"/>
            <mass value="1" />
            <inertia ixx="100" ixy="0" ixz="0" iyy="100" iyz="0" izz="100" />
        </inertial>
        <visual>
            <origin xyz="0 0 5" rpy="0 0 0"/>
            <geometry>
                <box size="0.75 0.75 0.75" />
            </geometry>
            <material name="Has sensor">
                <color rgba="0.2 0.66 0.31 1.0"/>
            </material>
        </visual>
        <collision>
            <origin xyz="0 0 5" rpy="0 0 0"/>
            <geometry>
                <box size="0.75 0.75 0.75" />
            </geometry>
        </collision>
    </link>
    <joint name="0_1" type="revolute">
       <parent link="0"/>
       <child  link="1"/>
       <origin rpy="0 0 0" xyz="0.375 0.0 5.0" />
     <axis xyz="0 0 1"/>
       <limit effort="0.0" lower="-3.14159" upper="3.14159" velocity="0.0"/>
    </joint>
    <link name="1">
        <inertial>
            <origin xyz="0.35 0.0 0.0" rpy="0 0 0"/>
            <mass value="1" />
            <inertia ixx="100" ixy="0" ixz="0" iyy="100" iyz="0" izz="100" />
        </inertial>
        <visual>
            <origin xyz="0.35 0.0 0.0" rpy="0 0 0"/>
            <geometry>
                <box size="0.7 0.7 0.7" />
            </geometry>
            <material name="Has sensor">
                <color rgba="0.2 0.66 0.31 1.0"/>
            </material>
        </visual>
        <collision>
            <origin xyz="0.35 0.0 0.0" rpy="0 0 0"/>
            <geometry>
                <box size="0.7 0.7 0.7" />
            </geometry>
        </collision>
    </link>
    <joint name="1_2" type="revolute">
       <parent link="1"/>
       <child  link="2"/>
       <origin rpy="0 0 0" xyz="0.7 0.0 0.0" />
     <axis xyz="0 0 1"/>
       <limit effort="0.0" lower="-3.14159" upper="3.14159" velocity="0.0"/>
    </joint>
    <link name="2">
        <inertial>
            <origin xyz="0.325 0.0 0.0" rpy="0 0 0"/>
            <mass value="1" />
            <inertia ixx="100" ixy="0" ixz="0" iyy="100" iyz="0" izz="100" />
        </inertial>
        <visual>
            <origin xyz="0.325 0.0 0.0" rpy="0 0 0"/>
            <geometry>
                <box size="0.65 0.65 0.65" />
            </geometry>
            <material name="Has sensor">
                <color rgba="0.2 0.66 0.31 1.0"/>
            </material>
        </visual>
        <collision>
            <origin xyz="0.325 0.0 0.0" rpy="0 0 0"/>
            <geometry>
                <box size="0.65 0.65 0.65" />
            </geometry>
        </collision>
    </link>
    <joint name="0_3" type="revolute">
       <parent link="0"/>
       <child  link="3"/>
       <origin rpy="0 0 0" xyz="0.0 0.375 5.0" />
     <axis xyz="1 0 0"/>
       <limit effort="0.0" lower="-3.14159" upper="3.14159" velocity="0.0"/>
    </joint>
    <link name="3">
        <inertial>
            <origin xyz="0.0 0.2325969104152119 0.0" rpy="0 0 0"/>
            <mass value="1" />
            <inertia ixx="100" ixy="0" ixz="0" iyy="100" iyz="0" izz="100" />
        </inertial>
        <visual>
            <origin xyz="0.0 0.2325969104152119 0.0" rpy="0 0 0"/>
            <geometry>
                <box size="0.5644693896425469 0.4651938208304238 0.6730502677944556" />
            </geometry>
            <material name="No sensor">
                <color rgba="0.44 0.78 0.91 1.0"/>
            </material>
        </visual>
        <collision>
            <origin xyz="0.0 0.2325969104152119 0.0" rpy="0 0 0"/>
            <geometry>
                <box size="0.5644693896425469 0.4651938208304238 0.6730502677944556" />
            </geometry>
        </collision>
    </link>
    <joint name="0_4" type="revolute">
       <parent link="0"/>
       <child  link="4"/>
       <origin rpy="0 0 0" xyz="0.0 0.4651938208304238 0.0" />
     <axis xyz="1 0 0"/>
       <limit effort="0.0" lower="-3.14159" upper="3.14159" velocity="0.0"/>
    </joint>
    <link name="4">
        <inertial>
            <origin xyz="0.0 0.3036169665298055 0.0" rpy="0 0 0"/>
            <mass value="1" />
            <inertia ixx="100" ixy="0" ixz="0" iyy="100" iyz="0" izz="100" />
        </inertial>
        <visual>
            <origin xyz="0.0 0.3036169665298055 0.0" rpy="0 0 0"/>
            <geometry>
                <box size="0.4213867633700797 0.607233933059611 0.6831314615377744" />
            </geometry>
            <material name="No sensor">
                <color rgba="0.44 0.78 0.91 1.0"/>
            </material>
        </visual>
        <collision>
            <origin xyz="0.0 0.3036169665298055 0.0" rpy="0 0 0"/>
            <geometry>
                <box size="0.4213867633700797 0.607233933059611 0.6831314615377744" />
            </geometry>
        </collision>
    </link>
    <joint name="0_5" type="revolute">
       <parent link="0"/>
       <child  link="5"/>
       <origin rpy="0 0 0" xyz="0.0 0.607233933059611 0.0" />
     <axis xyz="1 0 0"/>
       <limit effort="0.0" lower="-3.14159" upper="3.14159" velocity="0.0"/>
    </joint>
    <link name="5">
        <inertial>
            <origin xyz="0.0 0.24010508026241156 0.0" rpy="0 0 0"/>
            <mass value="1" />
            <inertia ixx="100" ixy="0" ixz="0" iyy="100" iyz="0" izz="100" />
        </inertial>
        <visual>
            <origin xyz="0.0 0.24010508026241156 0.0" rpy="0 0 0"/>
            <geometry>
                <box size="0.2686775899345349 0.4802101605248231 0.620168697949366" />
            </geometry>
            <material name="No sensor">
                <color rgba="0.44 0.78 0.91 1.0"/>
            </material>
        </visual>
        <collision>
            <origin xyz="0.0 0.24010508026241156 0.0" rpy="0 0 0"/>
            <geometry>
                <box size="0.2686775899345349 0.4802101605248231 0.620168697949366" />
            </geometry>
        </collision>
    </link>
    <joint name="0_6" type="revolute">
       <parent link="0"/>
       <child  link="6"/>
       <origin rpy="0 0 0" xyz="0.0 0.4802101605248231 0.0" />
     <axis xyz="1 0 0"/>
       <limit effort="0.0" lower="-3.14159" upper="3.14159" velocity="0.0"/>
    </joint>
    <link name="6">
        <inertial>
            <origin xyz="0.0 0.2758708525020962 0.0" rpy="0 0 0"/>
            <mass value="1" />
            <inertia ixx="100" ixy="0" ixz="0" iyy="100" iyz="0" izz="100" />
        </inertial>
        <visual>
            <origin xyz="0.0 0.2758708525020962 0.0" rpy="0 0 0"/>
            <geometry>
                <box size="0.26996744115432975 0.5517417050041924 0.30860090922552535" />
            </geometry>
            <material name="Has sensor">
                <color rgba="0.2 0.66 0.31 1.0"/>
            </material>
        </visual>
        <collision>
            <origin xyz="0.0 0.2758708525020962 0.0" rpy="0 0 0"/>
            <geometry>
                <box size="0.26996744115432975 0.5517417050041924 0.30860090922552535" />
            </geometry>
        </collision>
    </link>
    <joint name="0_7" type="revolute">
       <parent link="0"/>
       <child  link="7"/>
       <origin rpy="0 0 0" xyz="0.0 -0.375 5.0" />
     <axis xyz="1 0 0"/>
       <limit effort="0.0" lower="-3.14159" upper="3.14159" velocity="0.0"/>
    </joint>
    <link name="7">
        <inertial>
            <origin xyz="0.0 -0.2671009833210861 0.0" rpy="0 0 0"/>
            <mass value="1" />
            <inertia ixx="100" ixy="0" ixz="0" iyy="100" iyz="0" izz="100" />
        </inertial>
        <visual>
            <origin xyz="0.0 -0.2671009833210861 0.0" rpy="0 0 0"/>
            <geometry>
                <box size="0.2681185342104247 0.5342019666421722 0.7207804072059981" />
            </geometry>
            <material name="Has sensor">
                <color rgba="0.2 0.66 0.31 1.0"/>
            </material>
        </visual>
        <collision>
            <origin xyz="0.0 -0.2671009833210861 0.0" rpy="0 0 0"/>
            <geometry>
                <box size="0.2681185342104247 0.5342019666421722 0.7207804072059981" />
            </geometry>
        </collision>
    </link>
    <joint name="0_8" type="revolute">
       <parent link="0"/>
       <child  link="8"/>
       <origin rpy="0 0 0" xyz="0.0 -0.5342019666421722 0.0" />
     <axis xyz="1 0 0"/>
       <limit effort="0.0" lower="-3.14159" upper="3.14159" velocity="0.0"/>
    </joint>
    <link name="8">
        <inertial>
            <origin xyz="0.0 -0.3696571200439306 0.0" rpy="0 0 0"/>
            <mass value="1" />
            <inertia ixx="100" ixy="0" ixz="0" iyy="100" iyz="0" izz="100" />
        </inertial>
        <visual>
            <origin xyz="0.0 -0.3696571200439306 0.0" rpy="0 0 0"/>
            <geometry>
                <box size="0.7331574134223287 0.7393142400878612 0.34338770272207586" />
            </geometry>
            <material name="No sensor">
                <color rgba="0.44 0.78 0.91 1.0"/>
            </material>
        </visual>
        <collision>
            <origin xyz="0.0 -0.3696571200439306 0.0" rpy="0 0 0"/>
            <geometry>
                <box size="0.7331574134223287 0.7393142400878612 0.34338770272207586" />
            </geometry>
        </collision>
    </link>
    <joint name="0_9" type="revolute">
       <parent link="0"/>
       <child  link="9"/>
       <origin rpy="0 0 0" xyz="0.0 -0.7393142400878612 0.0" />
     <axis xyz="0 0 1"/>
       <limit effort="0.0" lower="-3.14159" upper="3.14159" velocity="0.0"/>
    </joint>
    <link name="9">
        <inertial>
            <origin xyz="0.0 -0.17023939222869883 0.0" rpy="0 0 0"/>
            <mass value="1" />
            <inertia ixx="100" ixy="0" ixz="0" iyy="100" iyz="0" izz="100" />
        </inertial>
        <visual>
            <origin xyz="0.0 -0.17023939222869883 0.0" rpy="0 0 0"/>
            <geometry>
                <box size="0.5449819502107278 0.34047878445739765 0.5438977292615275" />
            </geometry>
            <material name="Has sensor">
                <color rgba="0.2 0.66 0.31 1.0"/>
            </material>
        </visual>
        <collision>
            <origin xyz="0.0 -0.17023939222869883 0.0" rpy="0 0 0"/>
            <geometry>
                <box size="0.5449819502107278 0.34047878445739765 0.5438977292615275" />
            </geometry>
        </collision>
    </link>
    <joint name="0_10" type="revolute">
       <parent link="0"/>
       <child  link="10"/>
       <origin rpy="0 0 0" xyz="0.0 -0.34047878445739765 0.0" />
     <axis xyz="0 0 1"/>
       <limit effort="0.0" lower="-3.14159" upper="3.14159" velocity="0.0"/>
    </joint>
    <link name="10">
        <inertial>
            <origin xyz="0.0 -0.21551077265964047 0.0" rpy="0 0 0"/>
            <mass value="1" />
            <inertia ixx="100" ixy="0" ixz="0" iyy="100" iyz="0" izz="100" />
        </inertial>
        <visual>
            <origin xyz="0.0 -0.21551077265964047 0.0" rpy="0 0 0"/>
            <geometry>
                <box size="0.39830268913418493 0.43102154531928094 0.5282662108559393" />
            </geometry>
            <material name="Has sensor">
                <color rgba="0.2 0.66 0.31 1.0"/>
            </material>
        </visual>
        <collision>
            <origin xyz="0.0 -0.21551077265964047 0.0" rpy="0 0 0"/>
            <geometry>
                <box size="0.39830268913418493 0.43102154531928094 0.5282662108559393" />
            </geometry>
        </collision>
    </link>
    <joint name="0_11" type="revolute">
       <parent link="0"/>
       <child  link="11"/>
       <origin rpy="0 0 0" xyz="0.0 -0.43102154531928094 0.0" />
     <axis xyz="1 0 0"/>
       <limit effort="0.0" lower="-3.14159" upper="3.14159" velocity="0.0"/>
    </joint>
    <link name="11">
        <inertial>
            <origin xyz="0.0 -0.3667535185100813 0.0" rpy="0 0 0"/>
            <mass value="1" />
            <inertia ixx="100" ixy="0" ixz="0" iyy="100" iyz="0" izz="100" />
        </inertial>
        <visual>
            <origin xyz="0.0 -0.3667535185100813 0.0" rpy="0 0 0"/>
            <geometry>
                <box size="0.38683157132611895 0.7335070370201626 0.5911858184160823" />
            </geometry>
            <material name="Has sensor">
                <color rgba="0.2 0.66 0.31 1.0"/>
            </material>
        </visual>
        <collision>
            <origin xyz="0.0 -0.3667535185100813 0.0" rpy="0 0 0"/>
            <geometry>
                <box size="0.38683157132611895 0.7335070370201626 0.5911858184160823" />
            </geometry>
        </collision>
    </link>
    <joint name="2_12" type="revolute">
       <parent link="2"/>
       <child  link="12"/>
       <origin rpy="0 0 0" xyz="0.325 0.325 0.0" />
     <axis xyz="1 0 0"/>
       <limit effort="0.0" lower="-3.14159" upper="3.14159" velocity="0.0"/>
    </joint>
    <link name="12">
        <inertial>
            <origin xyz="0.0 0.24599716631069465 0.0" rpy="0 0 0"/>
            <mass value="1" />
            <inertia ixx="100" ixy="0" ixz="0" iyy="100" iyz="0" izz="100" />
        </inertial>
        <visual>
            <origin xyz="0.0 0.24599716631069465 0.0" rpy="0 0 0"/>
            <geometry>
                <box size="0.5609249590478376 0.4919943326213893 0.5692506296321147" />
            </geometry>
            <material name="No sensor">
                <color rgba="0.44 0.78 0.91 1.0"/>
            </material>
        </visual>
        <collision>
            <origin xyz="0.0 0.24599716631069465 0.0" rpy="0 0 0"/>
            <geometry>
                <box size="0.5609249590478376 0.4919943326213893 0.5692506296321147" />
            </geometry>
        </collision>
    </link>
    <joint name="2_13" type="revolute">
       <parent link="2"/>
       <child  link="13"/>
       <origin rpy="0 0 0" xyz="0.0 0.4919943326213893 0.0" />
     <axis xyz="1 0 0"/>
       <limit effort="0.0" lower="-3.14159" upper="3.14159" velocity="0.0"/>
    </joint>
    <link name="13">
        <inertial>
            <origin xyz="0.0 0.2859057259546154 0.0" rpy="0 0 0"/>
            <mass value="1" />
            <inertia ixx="100" ixy="0" ixz="0" iyy="100" iyz="0" izz="100" />
        </inertial>
        <visual>
            <origin xyz="0.0 0.2859057259546154 0.0" rpy="0 0 0"/>
            <geometry>
                <box size="0.3130687931761728 0.5718114519092308 0.7051599955051218" />
            </geometry>
            <material name="No sensor">
                <color rgba="0.44 0.78 0.91 1.0"/>
            </material>
        </visual>
        <collision>
            <origin xyz="0.0 0.2859057259546154 0.0" rpy="0 0 0"/>
            <geometry>
                <box size="0.3130687931761728 0.5718114519092308 0.7051599955051218" />
            </geometry>
        </collision>
    </link>
    <joint name="2_14" type="revolute">
       <parent link="2"/>
       <child  link="14"/>
       <origin rpy="0 0 0" xyz="0.0 0.5718114519092308 0.0" />
     <axis xyz="0 0 1"/>
       <limit effort="0.0" lower="-3.14159" upper="3.14159" velocity="0.0"/>
    </joint>
    <link name="14">
        <inertial>
            <origin xyz="0.0 0.2412701021939993 0.0" rpy="0 0 0"/>
            <mass value="1" />
            <inertia ixx="100" ixy="0" ixz="0" iyy="100" iyz="0" izz="100" />
        </inertial>
        <visual>
            <origin xyz="0.0 0.2412701021939993 0.0" rpy="0 0 0"/>
            <geometry>
                <box size="0.733333923899696 0.4825402043879986 0.5054196168276873" />
            </geometry>
            <material name="No sensor">
                <color rgba="0.44 0.78 0.91 1.0"/>
            </material>
        </visual>
        <collision>
            <origin xyz="0.0 0.2412701021939993 0.0" rpy="0 0 0"/>
            <geometry>
                <box size="0.733333923899696 0.4825402043879986 0.5054196168276873" />
            </geometry>
        </collision>
    </link>
    <joint name="2_15" type="revolute">
       <parent link="2"/>
       <child  link="15"/>
       <origin rpy="0 0 0" xyz="0.0 0.4825402043879986 0.0" />
     <axis xyz="1 0 0"/>
       <limit effort="0.0" lower="-3.14159" upper="3.14159" velocity="0.0"/>
    </joint>
    <link name="15">
        <inertial>
            <origin xyz="0.0 0.14947751723311656 0.0" rpy="0 0 0"/>
            <mass value="1" />
            <inertia ixx="100" ixy="0" ixz="0" iyy="100" iyz="0" izz="100" />
        </inertial>
        <visual>
            <origin xyz="0.0 0.14947751723311656 0.0" rpy="0 0 0"/>
            <geometry>
                <box size="0.2548117839747016 0.2989550344662331 0.27991134539984047" />
            </geometry>
            <material name="No sensor">
                <color rgba="0.44 0.78 0.91 1.0"/>
            </material>
        </visual>
        <collision>
            <origin xyz="0.0 0.14947751723311656 0.0" rpy="0 0 0"/>
            <geometry>
                <box size="0.2548117839747016 0.2989550344662331 0.27991134539984047" />
            </geometry>
        </collision>
    </link>
    <joint name="2_16" type="revolute">
       <parent link="2"/>
       <child  link="16"/>
       <origin rpy="0 0 0" xyz="0.325 -0.325 0.0" />
     <axis xyz="1 0 0"/>
       <limit effort="0.0" lower="-3.14159" upper="3.14159" velocity="0.0"/>
    </joint>
    <link name="16">
        <inertial>
            <origin xyz="0.0 -0.18719667846762839 0.0" rpy="0 0 0"/>
            <mass value="1" />
            <inertia ixx="100" ixy="0" ixz="0" iyy="100" iyz="0" izz="100" />
        </inertial>
        <visual>
            <origin xyz="0.0 -0.18719667846762839 0.0" rpy="0 0 0"/>
            <geometry>
                <box size="0.626849241786697 0.37439335693525677 0.3473206801496966" />
            </geometry>
            <material name="Has sensor">
                <color rgba="0.2 0.66 0.31 1.0"/>
            </material>
        </visual>
        <collision>
            <origin xyz="0.0 -0.18719667846762839 0.0" rpy="0 0 0"/>
            <geometry>
                <box size="0.626849241786697 0.37439335693525677 0.3473206801496966" />
            </geometry>
        </collision>
    </link>
    <joint name="2_17" type="revolute">
       <parent link="2"/>
       <child  link="17"/>
       <origin rpy="0 0 0" xyz="0.0 -0.37439335693525677 0.0" />
     <axis xyz="0 0 1"/>
       <limit effort="0.0" lower="-3.14159" upper="3.14159" velocity="0.0"/>
    </joint>
    <link name="17">
        <inertial>
            <origin xyz="0.0 -0.18598307705595502 0.0" rpy="0 0 0"/>
            <mass value="1" />
            <inertia ixx="100" ixy="0" ixz="0" iyy="100" iyz="0" izz="100" />
        </inertial>
        <visual>
            <origin xyz="0.0 -0.18598307705595502 0.0" rpy="0 0 0"/>
            <geometry>
                <box size="0.7320669809691642 0.37196615411191003 0.7337059321260204" />
            </geometry>
            <material name="Has sensor">
                <color rgba="0.2 0.66 0.31 1.0"/>
            </material>
        </visual>
        <collision>
            <origin xyz="0.0 -0.18598307705595502 0.0" rpy="0 0 0"/>
            <geometry>
                <box size="0.7320669809691642 0.37196615411191003 0.7337059321260204" />
            </geometry>
        </collision>
    </link>
    <joint name="2_18" type="revolute">
       <parent link="2"/>
       <child  link="18"/>
       <origin rpy="0 0 0" xyz="0.0 -0.37196615411191003 0.0" />
     <axis xyz="0 0 1"/>
       <limit effort="0.0" lower="-3.14159" upper="3.14159" velocity="0.0"/>
    </joint>
    <link name="18">
        <inertial>
            <origin xyz="0.0 -0.20587362977870333 0.0" rpy="0 0 0"/>
            <mass value="1" />
            <inertia ixx="100" ixy="0" ixz="0" iyy="100" iyz="0" izz="100" />
        </inertial>
        <visual>
            <origin xyz="0.0 -0.20587362977870333 0.0" rpy="0 0 0"/>
            <geometry>
                <box size="0.5675892067923274 0.41174725955740665 0.553734656925986" />
            </geometry>
            <material name="Has sensor">
                <color rgba="0.2 0.66 0.31 1.0"/>
            </material>
        </visual>
        <collision>
            <origin xyz="0.0 -0.20587362977870333 0.0" rpy="0 0 0"/>
            <geometry>
                <box size="0.5675892067923274 0.41174725955740665 0.553734656925986" />
            </geometry>
        </collision>
    </link>
    <joint name="2_19" type="revolute">
       <parent link="2"/>
       <child  link="19"/>
       <origin rpy="0 0 0" xyz="0.0 -0.41174725955740665 0.0" />
     <axis xyz="0 0 1"/>
       <limit effort="0.0" lower="-3.14159" upper="3.14159" velocity="0.0"/>
    </joint>
    <link name="19">
        <inertial>
            <origin xyz="0.0 -0.16935389214660532 0.0" rpy="0 0 0"/>
            <mass value="1" />
            <inertia ixx="100" ixy="0" ixz="0" iyy="100" iyz="0" izz="100" />
        </inertial>
        <visual>
            <origin xyz="0.0 -0.16935389214660532 0.0" rpy="0 0 0"/>
            <geometry>
                <box size="0.5052563891017875 0.33870778429321063 0.544211495985158" />
            </geometry>
            <material name="Has sensor">
                <color rgba="0.2 0.66 0.31 1.0"/>
            </material>
        </visual>
        <collision>
            <origin xyz="0.0 -0.16935389214660532 0.0" rpy="0 0 0"/>
            <geometry>
                <box size="0.5052563891017875 0.33870778429321063 0.544211495985158" />
            </geometry>
        </collision>
    </link>
    <joint name="2_20" type="revolute">
       <parent link="2"/>
       <child  link="20"/>
       <origin rpy="0 0 0" xyz="0.0 -0.33870778429321063 0.0" />
     <axis xyz="1 0 0"/>
       <limit effort="0.0" lower="-3.14159" upper="3.14159" velocity="0.0"/>
    </joint>
    <link name="20">
        <inertial>
            <origin xyz="0.0 -0.1525648493706356 0.0" rpy="0 0 0"/>
            <mass value="1" />
            <inertia ixx="100" ixy="0" ixz="0" iyy="100" iyz="0" izz="100" />
        </inertial>
        <visual>
            <origin xyz="0.0 -0.1525648493706356 0.0" rpy="0 0 0"/>
            <geometry>
                <box size="0.3024195688827394 0.3051296987412712 0.7014123391146975" />
            </geometry>
            <material name="No sensor">
                <color rgba="0.44 0.78 0.91 1.0"/>
            </material>
        </visual>
        <collision>
            <origin xyz="0.0 -0.1525648493706356 0.0" rpy="0 0 0"/>
            <geometry>
                <box size="0.3024195688827394 0.3051296987412712 0.7014123391146975" />
            </geometry>
        </collision>
    </link>
</robot>