<robot name = "robot">
    <link name="0">
        <inertial>
            <origin xyz="0 0 5" rpy="0 0 0"/>
            <mass value="1" />
            <inertia ixx="100" ixy="0" ixz="0" iyy="100" iyz="0" izz="100" />
        </inertial>
        <visual>
            <origin xyz="0 0 5" rpy="0 0 0"/>
            <geometry>
                <box size="0.75 0.75 0.75" />
            </geometry>
            <material name="Has sensor">
                <color rgba="0.2 0.66 0.31 1.0"/>
            </material>
        </visual>
        <collision>
            <origin xyz="0 0 5" rpy="0 0 0"/>
            <geometry>
                <box size="0.75 0.75 0.75" />
            </geometry>
        </collision>
    </link>
    <joint name="0_1" type="revolute">
       <parent link="0"/>
       <child  link="1"/>
       <origin rpy="0 0 0" xyz="0.375 0.0 5.0" />
     <axis xyz="0 1 0"/>
       <limit effort="0.0" lower="-3.14159" upper="3.14159" velocity="0.0"/>
    </joint>
    <link name="1">
        <inertial>
            <origin xyz="0.35 0.0 0.0" rpy="0 0 0"/>
            <mass value="1" />
            <inertia ixx="100" ixy="0" ixz="0" iyy="100" iyz="0" izz="100" />
        </inertial>
        <visual>
            <origin xyz="0.35 0.0 0.0" rpy="0 0 0"/>
            <geometry>
                <box size="0.7 0.7 0.7" />
            </geometry>
            <material name="Has sensor">
                <color rgba="0.2 0.66 0.31 1.0"/>
            </material>
        </visual>
        <collision>
            <origin xyz="0.35 0.0 0.0" rpy="0 0 0"/>
            <geometry>
                <box size="0.7 0.7 0.7" />
            </geometry>
        </collision>
    </link>
    <joint name="1_2" type="revolute">
       <parent link="1"/>
       <child  link="2"/>
       <origin rpy="0 0 0" xyz="0.7 0.0 0.0" />
     <axis xyz="0 0 1"/>
       <limit effort="0.0" lower="-3.14159" upper="3.14159" velocity="0.0"/>
    </joint>
    <link name="2">
        <inertial>
            <origin xyz="0.325 0.0 0.0" rpy="0 0 0"/>
            <mass value="1" />
            <inertia ixx="100" ixy="0" ixz="0" iyy="100" iyz="0" izz="100" />
        </inertial>
        <visual>
            <origin xyz="0.325 0.0 0.0" rpy="0 0 0"/>
            <geometry>
                <box size="0.65 0.65 0.65" />
            </geometry>
            <material name="Has sensor">
                <color rgba="0.2 0.66 0.31 1.0"/>
            </material>
        </visual>
        <collision>
            <origin xyz="0.325 0.0 0.0" rpy="0 0 0"/>
            <geometry>
                <box size="0.65 0.65 0.65" />
            </geometry>
        </collision>
    </link>
    <joint name="0_3" type="revolute">
       <parent link="0"/>
       <child  link="3"/>
       <origin rpy="0 0 0" xyz="0.0 0.0 5.375" />
     <axis xyz="0 1 0"/>
       <limit effort="0.0" lower="-3.14159" upper="3.14159" velocity="0.0"/>
    </joint>
    <link name="3">
        <inertial>
            <origin xyz="0.0 0.0 0.15386018226057557" rpy="0 0 0"/>
            <mass value="1" />
            <inertia ixx="100" ixy="0" ixz="0" iyy="100" iyz="0" izz="100" />
        </inertial>
        <visual>
            <origin xyz="0.0 0.0 0.15386018226057557" rpy="0 0 0"/>
            <geometry>
                <box size="0.3383334416486982 0.3033333590864685 0.30772036452115115" />
            </geometry>
            <material name="No sensor">
                <color rgba="0.44 0.78 0.91 1.0"/>
            </material>
        </visual>
        <collision>
            <origin xyz="0.0 0.0 0.15386018226057557" rpy="0 0 0"/>
            <geometry>
                <box size="0.3383334416486982 0.3033333590864685 0.30772036452115115" />
            </geometry>
        </collision>
    </link>
    <joint name="0_4" type="revolute">
       <parent link="0"/>
       <child  link="4"/>
       <origin rpy="0 0 0" xyz="0.0 0.0 0.30772036452115115" />
     <axis xyz="1 0 0"/>
       <limit effort="0.0" lower="-3.14159" upper="3.14159" velocity="0.0"/>
    </joint>
    <link name="4">
        <inertial>
            <origin xyz="0.0 0.0 0.21835517103312116" rpy="0 0 0"/>
            <mass value="1" />
            <inertia ixx="100" ixy="0" ixz="0" iyy="100" iyz="0" izz="100" />
        </inertial>
        <visual>
            <origin xyz="0.0 0.0 0.21835517103312116" rpy="0 0 0"/>
            <geometry>
                <box size="0.3704526093655889 0.4944926122405848 0.4367103420662423" />
            </geometry>
            <material name="No sensor">
                <color rgba="0.44 0.78 0.91 1.0"/>
            </material>
        </visual>
        <collision>
            <origin xyz="0.0 0.0 0.21835517103312116" rpy="0 0 0"/>
            <geometry>
                <box size="0.3704526093655889 0.4944926122405848 0.4367103420662423" />
            </geometry>
        </collision>
    </link>
    <joint name="0_5" type="revolute">
       <parent link="0"/>
       <child  link="5"/>
       <origin rpy="0 0 0" xyz="0.0 0.0 0.4367103420662423" />
     <axis xyz="1 0 0"/>
       <limit effort="0.0" lower="-3.14159" upper="3.14159" velocity="0.0"/>
    </joint>
    <link name="5">
        <inertial>
            <origin xyz="0.0 0.0 0.3456131017697312" rpy="0 0 0"/>
            <mass value="1" />
            <inertia ixx="100" ixy="0" ixz="0" iyy="100" iyz="0" izz="100" />
        </inertial>
        <visual>
            <origin xyz="0.0 0.0 0.3456131017697312" rpy="0 0 0"/>
            <geometry>
                <box size="0.4638653509732514 0.6341767353666519 0.6912262035394624" />
            </geometry>
            <material name="Has sensor">
                <color rgba="0.2 0.66 0.31 1.0"/>
            </material>
        </visual>
        <collision>
            <origin xyz="0.0 0.0 0.3456131017697312" rpy="0 0 0"/>
            <geometry>
                <box size="0.4638653509732514 0.6341767353666519 0.6912262035394624" />
            </geometry>
        </collision>
    </link>
    <joint name="0_6" type="revolute">
       <parent link="0"/>
       <child  link="6"/>
       <origin rpy="0 0 0" xyz="0.0 0.0 0.6912262035394624" />
     <axis xyz="1 0 0"/>
       <limit effort="0.0" lower="-3.14159" upper="3.14159" velocity="0.0"/>
    </joint>
    <link name="6">
        <inertial>
            <origin xyz="0.0 0.0 0.29495457669938707" rpy="0 0 0"/>
            <mass value="1" />
            <inertia ixx="100" ixy="0" ixz="0" iyy="100" iyz="0" izz="100" />
        </inertial>
        <visual>
            <origin xyz="0.0 0.0 0.29495457669938707" rpy="0 0 0"/>
            <geometry>
                <box size="0.4080011514624584 0.6246894860926819 0.5899091533987741" />
            </geometry>
            <material name="No sensor">
                <color rgba="0.44 0.78 0.91 1.0"/>
            </material>
        </visual>
        <collision>
            <origin xyz="0.0 0.0 0.29495457669938707" rpy="0 0 0"/>
            <geometry>
                <box size="0.4080011514624584 0.6246894860926819 0.5899091533987741" />
            </geometry>
        </collision>
    </link>
    <joint name="0_7" type="revolute">
       <parent link="0"/>
       <child  link="7"/>
       <origin rpy="0 0 0" xyz="0.0 0.0 4.625" />
     <axis xyz="1 0 0"/>
       <limit effort="0.0" lower="-3.14159" upper="3.14159" velocity="0.0"/>
    </joint>
    <link name="7">
        <inertial>
            <origin xyz="0.0 0.0 -0.3105357757722813" rpy="0 0 0"/>
            <mass value="1" />
            <inertia ixx="100" ixy="0" ixz="0" iyy="100" iyz="0" izz="100" />
        </inertial>
        <visual>
            <origin xyz="0.0 0.0 -0.3105357757722813" rpy="0 0 0"/>
            <geometry>
                <box size="0.41454789054982694 0.7033342198719632 0.6210715515445626" />
            </geometry>
            <material name="Has sensor">
                <color rgba="0.2 0.66 0.31 1.0"/>
            </material>
        </visual>
        <collision>
            <origin xyz="0.0 0.0 -0.3105357757722813" rpy="0 0 0"/>
            <geometry>
                <box size="0.41454789054982694 0.7033342198719632 0.6210715515445626" />
            </geometry>
        </collision>
    </link>
    <joint name="0_8" type="revolute">
       <parent link="0"/>
       <child  link="8"/>
       <origin rpy="0 0 0" xyz="0.0 0.0 -0.6210715515445626" />
     <axis xyz="0 1 0"/>
       <limit effort="0.0" lower="-3.14159" upper="3.14159" velocity="0.0"/>
    </joint>
    <link name="8">
        <inertial>
            <origin xyz="0.0 0.0 -0.33004556192251167" rpy="0 0 0"/>
            <mass value="1" />
            <inertia ixx="100" ixy="0" ixz="0" iyy="100" iyz="0" izz="100" />
        </inertial>
        <visual>
            <origin xyz="0.0 0.0 -0.33004556192251167" rpy="0 0 0"/>
            <geometry>
                <box size="0.33693257418523836 0.6535248994375378 0.6600911238450233" />
            </geometry>
            <material name="No sensor">
                <color rgba="0.44 0.78 0.91 1.0"/>
            </material>
        </visual>
        <collision>
            <origin xyz="0.0 0.0 -0.33004556192251167" rpy="0 0 0"/>
            <geometry>
                <box size="0.33693257418523836 0.6535248994375378 0.6600911238450233" />
            </geometry>
        </collision>
    </link>
    <joint name="0_9" type="revolute">
       <parent link="0"/>
       <child  link="9"/>
       <origin rpy="0 0 0" xyz="0.0 0.0 -0.6600911238450233" />
     <axis xyz="1 0 0"/>
       <limit effort="0.0" lower="-3.14159" upper="3.14159" velocity="0.0"/>
    </joint>
    <link name="9">
        <inertial>
            <origin xyz="0.0 0.0 -0.2327497368391879" rpy="0 0 0"/>
            <mass value="1" />
            <inertia ixx="100" ixy="0" ixz="0" iyy="100" iyz="0" izz="100" />
        </inertial>
        <visual>
            <origin xyz="0.0 0.0 -0.2327497368391879" rpy="0 0 0"/>
            <geometry>
                <box size="0.37653024822686315 0.33175233583072233 0.4654994736783758" />
            </geometry>
            <material name="Has sensor">
                <color rgba="0.2 0.66 0.31 1.0"/>
            </material>
        </visual>
        <collision>
            <origin xyz="0.0 0.0 -0.2327497368391879" rpy="0 0 0"/>
            <geometry>
                <box size="0.37653024822686315 0.33175233583072233 0.4654994736783758" />
            </geometry>
        </collision>
    </link>
    <joint name="0_10" type="revolute">
       <parent link="0"/>
       <child  link="10"/>
       <origin rpy="0 0 0" xyz="0.0 0.0 -0.4654994736783758" />
     <axis xyz="0 1 0"/>
       <limit effort="0.0" lower="-3.14159" upper="3.14159" velocity="0.0"/>
    </joint>
    <link name="10">
        <inertial>
            <origin xyz="0.0 0.0 -0.36439737923278026" rpy="0 0 0"/>
            <mass value="1" />
            <inertia ixx="100" ixy="0" ixz="0" iyy="100" iyz="0" izz="100" />
        </inertial>
        <visual>
            <origin xyz="0.0 0.0 -0.36439737923278026" rpy="0 0 0"/>
            <geometry>
                <box size="0.6312335803232709 0.49846658980971503 0.7287947584655605" />
            </geometry>
            <material name="No sensor">
                <color rgba="0.44 0.78 0.91 1.0"/>
            </material>
        </visual>
        <collision>
            <origin xyz="0.0 0.0 -0.36439737923278026" rpy="0 0 0"/>
            <geometry>
                <box size="0.6312335803232709 0.49846658980971503 0.7287947584655605" />
            </geometry>
        </collision>
    </link>
    <joint name="0_11" type="revolute">
       <parent link="0"/>
       <child  link="11"/>
       <origin rpy="0 0 0" xyz="0.0 0.0 -0.7287947584655605" />
     <axis xyz="1 0 0"/>
       <limit effort="0.0" lower="-3.14159" upper="3.14159" velocity="0.0"/>
    </joint>
    <link name="11">
        <inertial>
            <origin xyz="0.0 0.0 -0.3592490683018964" rpy="0 0 0"/>
            <mass value="1" />
            <inertia ixx="100" ixy="0" ixz="0" iyy="100" iyz="0" izz="100" />
        </inertial>
        <visual>
            <origin xyz="0.0 0.0 -0.3592490683018964" rpy="0 0 0"/>
            <geometry>
                <box size="0.5344794683361648 0.39204296558732254 0.7184981366037928" />
            </geometry>
            <material name="No sensor">
                <color rgba="0.44 0.78 0.91 1.0"/>
            </material>
        </visual>
        <collision>
            <origin xyz="0.0 0.0 -0.3592490683018964" rpy="0 0 0"/>
            <geometry>
                <box size="0.5344794683361648 0.39204296558732254 0.7184981366037928" />
            </geometry>
        </collision>
    </link>
    <joint name="1_12" type="revolute">
       <parent link="1"/>
       <child  link="12"/>
       <origin rpy="0 0 0" xyz="0.35 0.0 0.35" />
     <axis xyz="1 0 0"/>
       <limit effort="0.0" lower="-3.14159" upper="3.14159" velocity="0.0"/>
    </joint>
    <link name="12">
        <inertial>
            <origin xyz="0.0 0.0 0.22217083593412687" rpy="0 0 0"/>
            <mass value="1" />
            <inertia ixx="100" ixy="0" ixz="0" iyy="100" iyz="0" izz="100" />
        </inertial>
        <visual>
            <origin xyz="0.0 0.0 0.22217083593412687" rpy="0 0 0"/>
            <geometry>
                <box size="0.25264641175933966 0.5837159752826058 0.44434167186825374" />
            </geometry>
            <material name="No sensor">
                <color rgba="0.44 0.78 0.91 1.0"/>
            </material>
        </visual>
        <collision>
            <origin xyz="0.0 0.0 0.22217083593412687" rpy="0 0 0"/>
            <geometry>
                <box size="0.25264641175933966 0.5837159752826058 0.44434167186825374" />
            </geometry>
        </collision>
    </link>
    <joint name="1_13" type="revolute">
       <parent link="1"/>
       <child  link="13"/>
       <origin rpy="0 0 0" xyz="0.0 0.0 0.44434167186825374" />
     <axis xyz="1 0 0"/>
       <limit effort="0.0" lower="-3.14159" upper="3.14159" velocity="0.0"/>
    </joint>
    <link name="13">
        <inertial>
            <origin xyz="0.0 0.0 0.3734675746194077" rpy="0 0 0"/>
            <mass value="1" />
            <inertia ixx="100" ixy="0" ixz="0" iyy="100" iyz="0" izz="100" />
        </inertial>
        <visual>
            <origin xyz="0.0 0.0 0.3734675746194077" rpy="0 0 0"/>
            <geometry>
                <box size="0.3160923247816352 0.38828843595265794 0.7469351492388154" />
            </geometry>
            <material name="No sensor">
                <color rgba="0.44 0.78 0.91 1.0"/>
            </material>
        </visual>
        <collision>
            <origin xyz="0.0 0.0 0.3734675746194077" rpy="0 0 0"/>
            <geometry>
                <box size="0.3160923247816352 0.38828843595265794 0.7469351492388154" />
            </geometry>
        </collision>
    </link>
    <joint name="1_14" type="revolute">
       <parent link="1"/>
       <child  link="14"/>
       <origin rpy="0 0 0" xyz="0.0 0.0 0.7469351492388154" />
     <axis xyz="0 1 0"/>
       <limit effort="0.0" lower="-3.14159" upper="3.14159" velocity="0.0"/>
    </joint>
    <link name="14">
        <inertial>
            <origin xyz="0.0 0.0 0.3748235291929423" rpy="0 0 0"/>
            <mass value="1" />
            <inertia ixx="100" ixy="0" ixz="0" iyy="100" iyz="0" izz="100" />
        </inertial>
        <visual>
            <origin xyz="0.0 0.0 0.3748235291929423" rpy="0 0 0"/>
            <geometry>
                <box size="0.2606867233256543 0.6131345800647656 0.7496470583858846" />
            </geometry>
            <material name="No sensor">
                <color rgba="0.44 0.78 0.91 1.0"/>
            </material>
        </visual>
        <collision>
            <origin xyz="0.0 0.0 0.3748235291929423" rpy="0 0 0"/>
            <geometry>
                <box size="0.2606867233256543 0.6131345800647656 0.7496470583858846" />
            </geometry>
        </collision>
    </link>
    <joint name="1_15" type="revolute">
       <parent link="1"/>
       <child  link="15"/>
       <origin rpy="0 0 0" xyz="0.0 0.0 0.7496470583858846" />
     <axis xyz="1 0 0"/>
       <limit effort="0.0" lower="-3.14159" upper="3.14159" velocity="0.0"/>
    </joint>
    <link name="15">
        <inertial>
            <origin xyz="0.0 0.0 0.17524902106748153" rpy="0 0 0"/>
            <mass value="1" />
            <inertia ixx="100" ixy="0" ixz="0" iyy="100" iyz="0" izz="100" />
        </inertial>
        <visual>
            <origin xyz="0.0 0.0 0.17524902106748153" rpy="0 0 0"/>
            <geometry>
                <box size="0.4164791555975476 0.26793101043713113 0.35049804213496305" />
            </geometry>
            <material name="Has sensor">
                <color rgba="0.2 0.66 0.31 1.0"/>
            </material>
        </visual>
        <collision>
            <origin xyz="0.0 0.0 0.17524902106748153" rpy="0 0 0"/>
            <geometry>
                <box size="0.4164791555975476 0.26793101043713113 0.35049804213496305" />
            </geometry>
        </collision>
    </link>
    <joint name="1_16" type="revolute">
       <parent link="1"/>
       <child  link="16"/>
       <origin rpy="0 0 0" xyz="0.35 0.0 -0.35" />
     <axis xyz="0 1 0"/>
       <limit effort="0.0" lower="-3.14159" upper="3.14159" velocity="0.0"/>
    </joint>
    <link name="16">
        <inertial>
            <origin xyz="0.0 0.0 -0.148075846833184" rpy="0 0 0"/>
            <mass value="1" />
            <inertia ixx="100" ixy="0" ixz="0" iyy="100" iyz="0" izz="100" />
        </inertial>
        <visual>
            <origin xyz="0.0 0.0 -0.148075846833184" rpy="0 0 0"/>
            <geometry>
                <box size="0.3252442698943568 0.6903868396737054 0.296151693666368" />
            </geometry>
            <material name="Has sensor">
                <color rgba="0.2 0.66 0.31 1.0"/>
            </material>
        </visual>
        <collision>
            <origin xyz="0.0 0.0 -0.148075846833184" rpy="0 0 0"/>
            <geometry>
                <box size="0.3252442698943568 0.6903868396737054 0.296151693666368" />
            </geometry>
        </collision>
    </link>
    <joint name="1_17" type="revolute">
       <parent link="1"/>
       <child  link="17"/>
       <origin rpy="0 0 0" xyz="0.0 0.0 -0.296151693666368" />
     <axis xyz="0 1 0"/>
       <limit effort="0.0" lower="-3.14159" upper="3.14159" velocity="0.0"/>
    </joint>
    <link name="17">
        <inertial>
            <origin xyz="0.0 0.0 -0.2593434603756527" rpy="0 0 0"/>
            <mass value="1" />
            <inertia ixx="100" ixy="0" ixz="0" iyy="100" iyz="0" izz="100" />
        </inertial>
        <visual>
            <origin xyz="0.0 0.0 -0.2593434603756527" rpy="0 0 0"/>
            <geometry>
                <box size="0.5222959067030578 0.6899191781581024 0.5186869207513054" />
            </geometry>
            <material name="No sensor">
                <color rgba="0.44 0.78 0.91 1.0"/>
            </material>
        </visual>
        <collision>
            <origin xyz="0.0 0.0 -0.2593434603756527" rpy="0 0 0"/>
            <geometry>
                <box size="0.5222959067030578 0.6899191781581024 0.5186869207513054" />
            </geometry>
        </collision>
    </link>
    <joint name="1_18" type="revolute">
       <parent link="1"/>
       <child  link="18"/>
       <origin rpy="0 0 0" xyz="0.0 0.0 -0.5186869207513054" />
     <axis xyz="1 0 0"/>
       <limit effort="0.0" lower="-3.14159" upper="3.14159" velocity="0.0"/>
    </joint>
    <link name="18">
        <inertial>
            <origin xyz="0.0 0.0 -0.31749990230708347" rpy="0 0 0"/>
            <mass value="1" />
            <inertia ixx="100" ixy="0" ixz="0" iyy="100" iyz="0" izz="100" />
        </inertial>
        <visual>
            <origin xyz="0.0 0.0 -0.31749990230708347" rpy="0 0 0"/>
            <geometry>
                <box size="0.7190693871439857 0.3449435577627174 0.6349998046141669" />
            </geometry>
            <material name="Has sensor">
                <color rgba="0.2 0.66 0.31 1.0"/>
            </material>
        </visual>
        <collision>
            <origin xyz="0.0 0.0 -0.31749990230708347" rpy="0 0 0"/>
            <geometry>
                <box size="0.7190693871439857 0.3449435577627174 0.6349998046141669" />
            </geometry>
        </collision>
    </link>
    <joint name="2_19" type="revolute">
       <parent link="2"/>
       <child  link="19"/>
       <origin rpy="0 0 0" xyz="0.325 0.325 0.0" />
     <axis xyz="0 0 1"/>
       <limit effort="0.0" lower="-3.14159" upper="3.14159" velocity="0.0"/>
    </joint>
    <link name="19">
        <inertial>
            <origin xyz="0.0 0.29875084973581584 0.0" rpy="0 0 0"/>
            <mass value="1" />
            <inertia ixx="100" ixy="0" ixz="0" iyy="100" iyz="0" izz="100" />
        </inertial>
        <visual>
            <origin xyz="0.0 0.29875084973581584 0.0" rpy="0 0 0"/>
            <geometry>
                <box size="0.4402569690512717 0.5975016994716317 0.4551258666643622" />
            </geometry>
            <material name="No sensor">
                <color rgba="0.44 0.78 0.91 1.0"/>
            </material>
        </visual>
        <collision>
            <origin xyz="0.0 0.29875084973581584 0.0" rpy="0 0 0"/>
            <geometry>
                <box size="0.4402569690512717 0.5975016994716317 0.4551258666643622" />
            </geometry>
        </collision>
    </link>
    <joint name="2_20" type="revolute">
       <parent link="2"/>
       <child  link="20"/>
       <origin rpy="0 0 0" xyz="0.0 0.5975016994716317 0.0" />
     <axis xyz="1 0 0"/>
       <limit effort="0.0" lower="-3.14159" upper="3.14159" velocity="0.0"/>
    </joint>
    <link name="20">
        <inertial>
            <origin xyz="0.0 0.22211489738586215 0.0" rpy="0 0 0"/>
            <mass value="1" />
            <inertia ixx="100" ixy="0" ixz="0" iyy="100" iyz="0" izz="100" />
        </inertial>
        <visual>
            <origin xyz="0.0 0.22211489738586215 0.0" rpy="0 0 0"/>
            <geometry>
                <box size="0.44294054695468515 0.4442297947717243 0.32050817213722527" />
            </geometry>
            <material name="No sensor">
                <color rgba="0.44 0.78 0.91 1.0"/>
            </material>
        </visual>
        <collision>
            <origin xyz="0.0 0.22211489738586215 0.0" rpy="0 0 0"/>
            <geometry>
                <box size="0.44294054695468515 0.4442297947717243 0.32050817213722527" />
            </geometry>
        </collision>
    </link>
    <joint name="2_21" type="revolute">
       <parent link="2"/>
       <child  link="21"/>
       <origin rpy="0 0 0" xyz="0.0 0.4442297947717243 0.0" />
     <axis xyz="0 0 1"/>
       <limit effort="0.0" lower="-3.14159" upper="3.14159" velocity="0.0"/>
    </joint>
    <link name="21">
        <inertial>
            <origin xyz="0.0 0.28375137459809974 0.0" rpy="0 0 0"/>
            <mass value="1" />
            <inertia ixx="100" ixy="0" ixz="0" iyy="100" iyz="0" izz="100" />
        </inertial>
        <visual>
            <origin xyz="0.0 0.28375137459809974 0.0" rpy="0 0 0"/>
            <geometry>
                <box size="0.4484679729374133 0.5675027491961995 0.3542242303287345" />
            </geometry>
            <material name="No sensor">
                <color rgba="0.44 0.78 0.91 1.0"/>
            </material>
        </visual>
        <collision>
            <origin xyz="0.0 0.28375137459809974 0.0" rpy="0 0 0"/>
            <geometry>
                <box size="0.4484679729374133 0.5675027491961995 0.3542242303287345" />
            </geometry>
        </collision>
    </link>
    <joint name="2_22" type="revolute">
       <parent link="2"/>
       <child  link="22"/>
       <origin rpy="0 0 0" xyz="0.325 -0.325 0.0" />
     <axis xyz="1 0 0"/>
       <limit effort="0.0" lower="-3.14159" upper="3.14159" velocity="0.0"/>
    </joint>
    <link name="22">
        <inertial>
            <origin xyz="0.0 -0.2786466164481844 0.0" rpy="0 0 0"/>
            <mass value="1" />
            <inertia ixx="100" ixy="0" ixz="0" iyy="100" iyz="0" izz="100" />
        </inertial>
        <visual>
            <origin xyz="0.0 -0.2786466164481844 0.0" rpy="0 0 0"/>
            <geometry>
                <box size="0.6001091985737029 0.5572932328963688 0.6416743165224132" />
            </geometry>
            <material name="No sensor">
                <color rgba="0.44 0.78 0.91 1.0"/>
            </material>
        </visual>
        <collision>
            <origin xyz="0.0 -0.2786466164481844 0.0" rpy="0 0 0"/>
            <geometry>
                <box size="0.6001091985737029 0.5572932328963688 0.6416743165224132" />
            </geometry>
        </collision>
    </link>
</robot>