<robot name = "robot">
    <link name="0">
        <inertial>
            <origin xyz="0 0 5" rpy="0 0 0"/>
            <mass value="1" />
            <inertia ixx="100" ixy="0" ixz="0" iyy="100" iyz="0" izz="100" />
        </inertial>
        <visual>
            <origin xyz="0 0 5" rpy="0 0 0"/>
            <geometry>
                <box size="0.6922211442329889 0.7223478616698422 0.49822911081857735" />
            </geometry>
            <material name="No sensor">
                <color rgba="0.44 0.78 0.91 1.0"/>
            </material>
        </visual>
        <collision>
            <origin xyz="0 0 5" rpy="0 0 0"/>
            <geometry>
                <box size="0.6922211442329889 0.7223478616698422 0.49822911081857735" />
            </geometry>
        </collision>
    </link>
    <joint name="0_1" type="revolute">
       <parent link="0"/>
       <child  link="1"/>
       <origin rpy="0 0 0" xyz="0.34611057211649443 0.0 5.0" />
     <axis xyz="0 1 0"/>
       <limit effort="0.0" lower="-3.14159" upper="3.14159" velocity="0.0"/>
    </joint>
    <link name="1">
        <inertial>
            <origin xyz="0.2123131569846787 0.0 0.0" rpy="0 0 0"/>
            <mass value="1" />
            <inertia ixx="100" ixy="0" ixz="0" iyy="100" iyz="0" izz="100" />
        </inertial>
        <visual>
            <origin xyz="0.2123131569846787 0.0 0.0" rpy="0 0 0"/>
            <geometry>
                <box size="0.4246263139693574 0.7275661590326445 0.66478972745211" />
            </geometry>
            <material name="No sensor">
                <color rgba="0.44 0.78 0.91 1.0"/>
            </material>
        </visual>
        <collision>
            <origin xyz="0.2123131569846787 0.0 0.0" rpy="0 0 0"/>
            <geometry>
                <box size="0.4246263139693574 0.7275661590326445 0.66478972745211" />
            </geometry>
        </collision>
    </link>
    <joint name="1_2" type="revolute">
       <parent link="1"/>
       <child  link="2"/>
       <origin rpy="0 0 0" xyz="0.4246263139693574 0.0 0.0" />
     <axis xyz="0 1 0"/>
       <limit effort="0.0" lower="-3.14159" upper="3.14159" velocity="0.0"/>
    </joint>
    <link name="2">
        <inertial>
            <origin xyz="0.14287270113645578 0.0 0.0" rpy="0 0 0"/>
            <mass value="1" />
            <inertia ixx="100" ixy="0" ixz="0" iyy="100" iyz="0" izz="100" />
        </inertial>
        <visual>
            <origin xyz="0.14287270113645578 0.0 0.0" rpy="0 0 0"/>
            <geometry>
                <box size="0.28574540227291156 0.6144007544732322 0.7138184607576912" />
            </geometry>
            <material name="Has sensor">
                <color rgba="0.2 0.66 0.31 1.0"/>
            </material>
        </visual>
        <collision>
            <origin xyz="0.14287270113645578 0.0 0.0" rpy="0 0 0"/>
            <geometry>
                <box size="0.28574540227291156 0.6144007544732322 0.7138184607576912" />
            </geometry>
        </collision>
    </link>
    <joint name="2_3" type="revolute">
       <parent link="2"/>
       <child  link="3"/>
       <origin rpy="0 0 0" xyz="0.28574540227291156 0.0 0.0" />
     <axis xyz="0 1 0"/>
       <limit effort="0.0" lower="-3.14159" upper="3.14159" velocity="0.0"/>
    </joint>
    <link name="3">
        <inertial>
            <origin xyz="0.17569815600474803 0.0 0.0" rpy="0 0 0"/>
            <mass value="1" />
            <inertia ixx="100" ixy="0" ixz="0" iyy="100" iyz="0" izz="100" />
        </inertial>
        <visual>
            <origin xyz="0.17569815600474803 0.0 0.0" rpy="0 0 0"/>
            <geometry>
                <box size="0.35139631200949606 0.5840566008444273 0.7097561920306478" />
            </geometry>
            <material name="Has sensor">
                <color rgba="0.2 0.66 0.31 1.0"/>
            </material>
        </visual>
        <collision>
            <origin xyz="0.17569815600474803 0.0 0.0" rpy="0 0 0"/>
            <geometry>
                <box size="0.35139631200949606 0.5840566008444273 0.7097561920306478" />
            </geometry>
        </collision>
    </link>
    <joint name="3_4" type="revolute">
       <parent link="3"/>
       <child  link="4"/>
       <origin rpy="0 0 0" xyz="0.35139631200949606 0.0 0.0" />
     <axis xyz="0 1 0"/>
       <limit effort="0.0" lower="-3.14159" upper="3.14159" velocity="0.0"/>
    </joint>
    <link name="4">
        <inertial>
            <origin xyz="0.33507098463630997 0.0 0.0" rpy="0 0 0"/>
            <mass value="1" />
            <inertia ixx="100" ixy="0" ixz="0" iyy="100" iyz="0" izz="100" />
        </inertial>
        <visual>
            <origin xyz="0.33507098463630997 0.0 0.0" rpy="0 0 0"/>
            <geometry>
                <box size="0.6701419692726199 0.7059259719808286 0.4373954283695172" />
            </geometry>
            <material name="Has sensor">
                <color rgba="0.2 0.66 0.31 1.0"/>
            </material>
        </visual>
        <collision>
            <origin xyz="0.33507098463630997 0.0 0.0" rpy="0 0 0"/>
            <geometry>
                <box size="0.6701419692726199 0.7059259719808286 0.4373954283695172" />
            </geometry>
        </collision>
    </link>
    <joint name="1_5" type="revolute">
       <parent link="1"/>
       <child  link="5"/>
       <origin rpy="0 0 0" xyz="0.2123131569846787 0.0 0.332394863726055" />
     <axis xyz="1 0 0"/>
       <limit effort="0.0" lower="-3.14159" upper="3.14159" velocity="0.0"/>
    </joint>
    <link name="5">
        <inertial>
            <origin xyz="0.0 0.0 0.1374205370208671" rpy="0 0 0"/>
            <mass value="1" />
            <inertia ixx="100" ixy="0" ixz="0" iyy="100" iyz="0" izz="100" />
        </inertial>
        <visual>
            <origin xyz="0.0 0.0 0.1374205370208671" rpy="0 0 0"/>
            <geometry>
                <box size="0.527651033511465 0.44059253974213386 0.3152845606850825" />
            </geometry>
            <material name="No sensor">
                <color rgba="0.44 0.78 0.91 1.0"/>
            </material>
        </visual>
        <collision>
            <origin xyz="0.0 0.0 0.1374205370208671" rpy="0 0 0"/>
            <geometry>
                <box size="0.527651033511465 0.44059253974213386 0.3152845606850825" />
            </geometry>
        </collision>
    </link>
    <joint name="1_6" type="revolute">
       <parent link="1"/>
       <child  link="6"/>
       <origin rpy="0 0 0" xyz="0.0 0.0 0.3152845606850825" />
     <axis xyz="1 0 0"/>
       <limit effort="0.0" lower="-3.14159" upper="3.14159" velocity="0.0"/>
    </joint>
    <link name="6">
        <inertial>
            <origin xyz="0.0 0.0 0.1374205370208671" rpy="0 0 0"/>
            <mass value="1" />
            <inertia ixx="100" ixy="0" ixz="0" iyy="100" iyz="0" izz="100" />
        </inertial>
        <visual>
            <origin xyz="0.0 0.0 0.1374205370208671" rpy="0 0 0"/>
            <geometry>
                <box size="0.5865549832155086 0.6098050611734672 0.2748410740417342" />
            </geometry>
            <material name="No sensor">
                <color rgba="0.44 0.78 0.91 1.0"/>
            </material>
        </visual>
        <collision>
            <origin xyz="0.0 0.0 0.1374205370208671" rpy="0 0 0"/>
            <geometry>
                <box size="0.5865549832155086 0.6098050611734672 0.2748410740417342" />
            </geometry>
        </collision>
    </link>
    <joint name="1_7" type="revolute">
       <parent link="1"/>
       <child  link="7"/>
       <origin rpy="0 0 0" xyz="0.0 0.0 0.2748410740417342" />
     <axis xyz="0 1 0"/>
       <limit effort="0.0" lower="-3.14159" upper="3.14159" velocity="0.0"/>
    </joint>
    <link name="7">
        <inertial>
            <origin xyz="0.0 0.0 0.35185690186024154" rpy="0 0 0"/>
            <mass value="1" />
            <inertia ixx="100" ixy="0" ixz="0" iyy="100" iyz="0" izz="100" />
        </inertial>
        <visual>
            <origin xyz="0.0 0.0 0.35185690186024154" rpy="0 0 0"/>
            <geometry>
                <box size="0.37865772677021065 0.5421300018797814 0.7037138037204831" />
            </geometry>
            <material name="Has sensor">
                <color rgba="0.2 0.66 0.31 1.0"/>
            </material>
        </visual>
        <collision>
            <origin xyz="0.0 0.0 0.35185690186024154" rpy="0 0 0"/>
            <geometry>
                <box size="0.37865772677021065 0.5421300018797814 0.7037138037204831" />
            </geometry>
        </collision>
    </link>
    <joint name="2_8" type="revolute">
       <parent link="2"/>
       <child  link="8"/>
       <origin rpy="0 0 0" xyz="0.14287270113645578 0.0 0.3569092303788456" />
     <axis xyz="0 1 0"/>
       <limit effort="0.0" lower="-3.14159" upper="3.14159" velocity="0.0"/>
    </joint>
    <link name="8">
        <inertial>
            <origin xyz="0.0 0.0 0.31353870656301064" rpy="0 0 0"/>
            <mass value="1" />
            <inertia ixx="100" ixy="0" ixz="0" iyy="100" iyz="0" izz="100" />
        </inertial>
        <visual>
            <origin xyz="0.0 0.0 0.31353870656301064" rpy="0 0 0"/>
            <geometry>
                <box size="0.5925138821570723 0.38384267682990997 0.4286333260089051" />
            </geometry>
            <material name="Has sensor">
                <color rgba="0.2 0.66 0.31 1.0"/>
            </material>
        </visual>
        <collision>
            <origin xyz="0.0 0.0 0.31353870656301064" rpy="0 0 0"/>
            <geometry>
                <box size="0.5925138821570723 0.38384267682990997 0.4286333260089051" />
            </geometry>
        </collision>
    </link>
    <joint name="2_9" type="revolute">
       <parent link="2"/>
       <child  link="9"/>
       <origin rpy="0 0 0" xyz="0.0 0.0 0.4286333260089051" />
     <axis xyz="1 0 0"/>
       <limit effort="0.0" lower="-3.14159" upper="3.14159" velocity="0.0"/>
    </joint>
    <link name="9">
        <inertial>
            <origin xyz="0.0 0.0 0.3605894420465704" rpy="0 0 0"/>
            <mass value="1" />
            <inertia ixx="100" ixy="0" ixz="0" iyy="100" iyz="0" izz="100" />
        </inertial>
        <visual>
            <origin xyz="0.0 0.0 0.3605894420465704" rpy="0 0 0"/>
            <geometry>
                <box size="0.540430961613331 0.6681772540047142 0.7211788840931408" />
            </geometry>
            <material name="No sensor">
                <color rgba="0.44 0.78 0.91 1.0"/>
            </material>
        </visual>
        <collision>
            <origin xyz="0.0 0.0 0.3605894420465704" rpy="0 0 0"/>
            <geometry>
                <box size="0.540430961613331 0.6681772540047142 0.7211788840931408" />
            </geometry>
        </collision>
    </link>
    <joint name="2_10" type="revolute">
       <parent link="2"/>
       <child  link="10"/>
       <origin rpy="0 0 0" xyz="0.0 0.0 0.7211788840931408" />
     <axis xyz="1 0 0"/>
       <limit effort="0.0" lower="-3.14159" upper="3.14159" velocity="0.0"/>
    </joint>
    <link name="10">
        <inertial>
            <origin xyz="0.0 0.0 0.31353870656301064" rpy="0 0 0"/>
            <mass value="1" />
            <inertia ixx="100" ixy="0" ixz="0" iyy="100" iyz="0" izz="100" />
        </inertial>
        <visual>
            <origin xyz="0.0 0.0 0.31353870656301064" rpy="0 0 0"/>
            <geometry>
                <box size="0.6241253838250692 0.5564078380437367 0.6270774131260213" />
            </geometry>
            <material name="Has sensor">
                <color rgba="0.2 0.66 0.31 1.0"/>
            </material>
        </visual>
        <collision>
            <origin xyz="0.0 0.0 0.31353870656301064" rpy="0 0 0"/>
            <geometry>
                <box size="0.6241253838250692 0.5564078380437367 0.6270774131260213" />
            </geometry>
        </collision>
    </link>
</robot>