<robot name = "robot">
    <link name="0">
        <inertial>
            <origin xyz="0 0 5" rpy="0 0 0"/>
            <mass value="1" />
            <inertia ixx="100" ixy="0" ixz="0" iyy="100" iyz="0" izz="100" />
        </inertial>
        <visual>
            <origin xyz="0 0 5" rpy="0 0 0"/>
            <geometry>
                <box size="0.39269735664029026 0.4694694912125661 0.7128868335230603" />
            </geometry>
            <material name="No sensor">
                <color rgba="0.44 0.78 0.91 1.0"/>
            </material>
        </visual>
        <collision>
            <origin xyz="0 0 5" rpy="0 0 0"/>
            <geometry>
                <box size="0.39269735664029026 0.4694694912125661 0.7128868335230603" />
            </geometry>
        </collision>
    </link>
    <joint name="0_1" type="revolute">
       <parent link="0"/>
       <child  link="1"/>
       <origin rpy="0 0 0" xyz="0.19634867832014513 0.0 5.0" />
     <axis xyz="0 0 1"/>
       <limit effort="0.0" lower="-3.14159" upper="3.14159" velocity="0.0"/>
    </joint>
    <link name="1">
        <inertial>
            <origin xyz="0.16275983268263788 0.0 0.0" rpy="0 0 0"/>
            <mass value="1" />
            <inertia ixx="100" ixy="0" ixz="0" iyy="100" iyz="0" izz="100" />
        </inertial>
        <visual>
            <origin xyz="0.16275983268263788 0.0 0.0" rpy="0 0 0"/>
            <geometry>
                <box size="0.6510393307305515 0.4884602181632194 0.49030825346076734" />
            </geometry>
            <material name="Has sensor">
                <color rgba="0.2 0.66 0.31 1.0"/>
            </material>
        </visual>
        <collision>
            <origin xyz="0.16275983268263788 0.0 0.0" rpy="0 0 0"/>
            <geometry>
                <box size="0.6510393307305515 0.4884602181632194 0.49030825346076734" />
            </geometry>
        </collision>
    </link>
    <joint name="1_2" type="revolute">
       <parent link="1"/>
       <child  link="2"/>
       <origin rpy="0 0 0" xyz="0.6510393307305515 0.0 0.0" />
     <axis xyz="0 1 0"/>
       <limit effort="0.0" lower="-3.14159" upper="3.14159" velocity="0.0"/>
    </joint>
    <link name="2">
        <inertial>
            <origin xyz="0.11482227788009475 0.0 0.0" rpy="0 0 0"/>
            <mass value="1" />
            <inertia ixx="100" ixy="0" ixz="0" iyy="100" iyz="0" izz="100" />
        </inertial>
        <visual>
            <origin xyz="0.11482227788009475 0.0 0.0" rpy="0 0 0"/>
            <geometry>
                <box size="0.459289111520379 0.5804749312112882 0.48922686613542227" />
            </geometry>
            <material name="Has sensor">
                <color rgba="0.2 0.66 0.31 1.0"/>
            </material>
        </visual>
        <collision>
            <origin xyz="0.11482227788009475 0.0 0.0" rpy="0 0 0"/>
            <geometry>
                <box size="0.459289111520379 0.5804749312112882 0.48922686613542227" />
            </geometry>
        </collision>
    </link>
    <joint name="2_3" type="revolute">
       <parent link="2"/>
       <child  link="3"/>
       <origin rpy="0 0 0" xyz="0.459289111520379 0.0 0.0" />
     <axis xyz="0 1 0"/>
       <limit effort="0.0" lower="-3.14159" upper="3.14159" velocity="0.0"/>
    </joint>
    <link name="3">
        <inertial>
            <origin xyz="0.11727616089555391 0.0 0.0" rpy="0 0 0"/>
            <mass value="1" />
            <inertia ixx="100" ixy="0" ixz="0" iyy="100" iyz="0" izz="100" />
        </inertial>
        <visual>
            <origin xyz="0.11727616089555391 0.0 0.0" rpy="0 0 0"/>
            <geometry>
                <box size="0.46910464358221565 0.4553741539584617 0.3650761315027437" />
            </geometry>
            <material name="No sensor">
                <color rgba="0.44 0.78 0.91 1.0"/>
            </material>
        </visual>
        <collision>
            <origin xyz="0.11727616089555391 0.0 0.0" rpy="0 0 0"/>
            <geometry>
                <box size="0.46910464358221565 0.4553741539584617 0.3650761315027437" />
            </geometry>
        </collision>
    </link>
    <joint name="3_4" type="revolute">
       <parent link="3"/>
       <child  link="4"/>
       <origin rpy="0 0 0" xyz="0.46910464358221565 0.0 0.0" />
     <axis xyz="0 0 1"/>
       <limit effort="0.0" lower="-3.14159" upper="3.14159" velocity="0.0"/>
    </joint>
    <link name="4">
        <inertial>
            <origin xyz="0.16185087625017264 0.0 0.0" rpy="0 0 0"/>
            <mass value="1" />
            <inertia ixx="100" ixy="0" ixz="0" iyy="100" iyz="0" izz="100" />
        </inertial>
        <visual>
            <origin xyz="0.16185087625017264 0.0 0.0" rpy="0 0 0"/>
            <geometry>
                <box size="0.6474035050006905 0.3723909493642308 0.5402604460541927" />
            </geometry>
            <material name="No sensor">
                <color rgba="0.44 0.78 0.91 1.0"/>
            </material>
        </visual>
        <collision>
            <origin xyz="0.16185087625017264 0.0 0.0" rpy="0 0 0"/>
            <geometry>
                <box size="0.6474035050006905 0.3723909493642308 0.5402604460541927" />
            </geometry>
        </collision>
    </link>
    <joint name="4_5" type="revolute">
       <parent link="4"/>
       <child  link="5"/>
       <origin rpy="0 0 0" xyz="0.6474035050006905 0.0 0.0" />
     <axis xyz="0 1 0"/>
       <limit effort="0.0" lower="-3.14159" upper="3.14159" velocity="0.0"/>
    </joint>
    <link name="5">
        <inertial>
            <origin xyz="0.0 0.15097543762858234 0.0" rpy="0 0 0"/>
            <mass value="1" />
            <inertia ixx="100" ixy="0" ixz="0" iyy="100" iyz="0" izz="100" />
        </inertial>
        <visual>
            <origin xyz="0.0 0.15097543762858234 0.0" rpy="0 0 0"/>
            <geometry>
                <box size="0.32762962764159764 0.6039017505143294 0.6238464162672602" />
            </geometry>
            <material name="No sensor">
                <color rgba="0.44 0.78 0.91 1.0"/>
            </material>
        </visual>
        <collision>
            <origin xyz="0.0 0.15097543762858234 0.0" rpy="0 0 0"/>
            <geometry>
                <box size="0.32762962764159764 0.6039017505143294 0.6238464162672602" />
            </geometry>
        </collision>
    </link>
    <joint name="5_6" type="revolute">
       <parent link="5"/>
       <child  link="6"/>
       <origin rpy="0 0 0" xyz="0.0 0.6039017505143294 0.0" />
     <axis xyz="0 0 1"/>
       <limit effort="0.0" lower="-3.14159" upper="3.14159" velocity="0.0"/>
    </joint>
    <link name="6">
        <inertial>
            <origin xyz="0.0 0.06529166512692369 0.0" rpy="0 0 0"/>
            <mass value="1" />
            <inertia ixx="100" ixy="0" ixz="0" iyy="100" iyz="0" izz="100" />
        </inertial>
        <visual>
            <origin xyz="0.0 0.06529166512692369 0.0" rpy="0 0 0"/>
            <geometry>
                <box size="0.41020697661227307 0.26116666050769477 0.47182148080061087" />
            </geometry>
            <material name="Has sensor">
                <color rgba="0.2 0.66 0.31 1.0"/>
            </material>
        </visual>
        <collision>
            <origin xyz="0.0 0.06529166512692369 0.0" rpy="0 0 0"/>
            <geometry>
                <box size="0.41020697661227307 0.26116666050769477 0.47182148080061087" />
            </geometry>
        </collision>
    </link>
    <joint name="6_7" type="revolute">
       <parent link="6"/>
       <child  link="7"/>
       <origin rpy="0 0 0" xyz="0.0 0.26116666050769477 0.0" />
     <axis xyz="0 1 0"/>
       <limit effort="0.0" lower="-3.14159" upper="3.14159" velocity="0.0"/>
    </joint>
    <link name="7">
        <inertial>
            <origin xyz="0.0 0.0 0.06774080034092203" rpy="0 0 0"/>
            <mass value="1" />
            <inertia ixx="100" ixy="0" ixz="0" iyy="100" iyz="0" izz="100" />
        </inertial>
        <visual>
            <origin xyz="0.0 0.0 0.06774080034092203" rpy="0 0 0"/>
            <geometry>
                <box size="0.6159484826320678 0.6368773756780469 0.2709632013636881" />
            </geometry>
            <material name="No sensor">
                <color rgba="0.44 0.78 0.91 1.0"/>
            </material>
        </visual>
        <collision>
            <origin xyz="0.0 0.0 0.06774080034092203" rpy="0 0 0"/>
            <geometry>
                <box size="0.6159484826320678 0.6368773756780469 0.2709632013636881" />
            </geometry>
        </collision>
    </link>
    <joint name="7_8" type="revolute">
       <parent link="7"/>
       <child  link="8"/>
       <origin rpy="0 0 0" xyz="0.0 0.0 0.2709632013636881" />
     <axis xyz="0 1 0"/>
       <limit effort="0.0" lower="-3.14159" upper="3.14159" velocity="0.0"/>
    </joint>
    <link name="8">
        <inertial>
            <origin xyz="0.0 0.1455303267232381 0.0" rpy="0 0 0"/>
            <mass value="1" />
            <inertia ixx="100" ixy="0" ixz="0" iyy="100" iyz="0" izz="100" />
        </inertial>
        <visual>
            <origin xyz="0.0 0.1455303267232381 0.0" rpy="0 0 0"/>
            <geometry>
                <box size="0.2817663977188753 0.5821213068929524 0.528163426659725" />
            </geometry>
            <material name="No sensor">
                <color rgba="0.44 0.78 0.91 1.0"/>
            </material>
        </visual>
        <collision>
            <origin xyz="0.0 0.1455303267232381 0.0" rpy="0 0 0"/>
            <geometry>
                <box size="0.2817663977188753 0.5821213068929524 0.528163426659725" />
            </geometry>
        </collision>
    </link>
    <joint name="8_9" type="revolute">
       <parent link="8"/>
       <child  link="9"/>
       <origin rpy="0 0 0" xyz="0.0 0.5821213068929524 0.0" />
     <axis xyz="0 0 1"/>
       <limit effort="0.0" lower="-3.14159" upper="3.14159" velocity="0.0"/>
    </joint>
    <link name="9">
        <inertial>
            <origin xyz="0.0 0.0 0.0706712005026497" rpy="0 0 0"/>
            <mass value="1" />
            <inertia ixx="100" ixy="0" ixz="0" iyy="100" iyz="0" izz="100" />
        </inertial>
        <visual>
            <origin xyz="0.0 0.0 0.0706712005026497" rpy="0 0 0"/>
            <geometry>
                <box size="0.3510022740778805 0.6534533501573407 0.2826848020105988" />
            </geometry>
            <material name="Has sensor">
                <color rgba="0.2 0.66 0.31 1.0"/>
            </material>
        </visual>
        <collision>
            <origin xyz="0.0 0.0 0.0706712005026497" rpy="0 0 0"/>
            <geometry>
                <box size="0.3510022740778805 0.6534533501573407 0.2826848020105988" />
            </geometry>
        </collision>
    </link>
</robot>