<robot name = "robot">
    <link name="0">
        <inertial>
            <origin xyz="0.8277634063454427 0 5" rpy="0 0 0"/>
            <mass value="1" />
            <inertia ixx="100" ixy="0" ixz="0" iyy="100" iyz="0" izz="100" />
        </inertial>
        <visual>
            <origin xyz="0.8277634063454427 0 5" rpy="0 0 0"/>
            <geometry>
                <box size="0.8277634063454427 0.7523800693034232 0.9693046781081779" />
            </geometry>
            <material name="No sensor">
                <color rgba="0.44 0.78 0.91 1.0"/>
            </material>
        </visual>
        <collision>
            <origin xyz="0.8277634063454427 0 5" rpy="0 0 0"/>
            <geometry>
                <box size="0.8277634063454427 0.7523800693034232 0.9693046781081779" />
            </geometry>
        </collision>
    </link>
    <joint name="0_1" type="revolute">
       <parent link="0"/>
       <child  link="1"/>
       <origin rpy="0 0 0" xyz="0.8277634063454427 0 5" />
     <axis xyz="0 0 1"/>
       <limit effort="0.0" lower="-3.14159" upper="3.14159" velocity="0.0"/>
    </joint>
    <link name="1">
        <inertial>
            <origin xyz="0.48788383099220556 0 5" rpy="0 0 0"/>
            <mass value="1" />
            <inertia ixx="100" ixy="0" ixz="0" iyy="100" iyz="0" izz="100" />
        </inertial>
        <visual>
            <origin xyz="0.48788383099220556 0 5" rpy="0 0 0"/>
            <geometry>
                <box size="0.9757676619844111 0.999152485627686 0.7937570277692297" />
            </geometry>
            <material name="No sensor">
                <color rgba="0.44 0.78 0.91 1.0"/>
            </material>
        </visual>
        <collision>
            <origin xyz="0.48788383099220556 0 5" rpy="0 0 0"/>
            <geometry>
                <box size="0.9757676619844111 0.999152485627686 0.7937570277692297" />
            </geometry>
        </collision>
    </link>
    <joint name="1_2" type="revolute">
       <parent link="1"/>
       <child  link="2"/>
       <origin rpy="0 0 0" xyz="0.9757676619844111 0 5" />
     <axis xyz="0 0 1"/>
       <limit effort="0.0" lower="-3.14159" upper="3.14159" velocity="0.0"/>
    </joint>
    <link name="2">
        <inertial>
            <origin xyz="0.4703183493199103 0 5" rpy="0 0 0"/>
            <mass value="1" />
            <inertia ixx="100" ixy="0" ixz="0" iyy="100" iyz="0" izz="100" />
        </inertial>
        <visual>
            <origin xyz="0.4703183493199103 0 5" rpy="0 0 0"/>
            <geometry>
                <box size="0.9406366986398206 0.9848106766591678 0.7813036990159566" />
            </geometry>
            <material name="Has sensor">
                <color rgba="0.2 0.66 0.31 1.0"/>
            </material>
        </visual>
        <collision>
            <origin xyz="0.4703183493199103 0 5" rpy="0 0 0"/>
            <geometry>
                <box size="0.9406366986398206 0.9848106766591678 0.7813036990159566" />
            </geometry>
        </collision>
    </link>
    <joint name="2_3" type="revolute">
       <parent link="2"/>
       <child  link="3"/>
       <origin rpy="0 0 0" xyz="0.9406366986398206 0 5" />
     <axis xyz="0 1 0"/>
       <limit effort="0.0" lower="-3.14159" upper="3.14159" velocity="0.0"/>
    </joint>
    <link name="3">
        <inertial>
            <origin xyz="0.37860818427632414 0 5" rpy="0 0 0"/>
            <mass value="1" />
            <inertia ixx="100" ixy="0" ixz="0" iyy="100" iyz="0" izz="100" />
        </inertial>
        <visual>
            <origin xyz="0.37860818427632414 0 5" rpy="0 0 0"/>
            <geometry>
                <box size="0.7572163685526483 0.7605811428417633 0.7665287295661583" />
            </geometry>
            <material name="Has sensor">
                <color rgba="0.2 0.66 0.31 1.0"/>
            </material>
        </visual>
        <collision>
            <origin xyz="0.37860818427632414 0 5" rpy="0 0 0"/>
            <geometry>
                <box size="0.7572163685526483 0.7605811428417633 0.7665287295661583" />
            </geometry>
        </collision>
    </link>
    <joint name="3_4" type="revolute">
       <parent link="3"/>
       <child  link="4"/>
       <origin rpy="0 0 0" xyz="0.7572163685526483 0 5" />
     <axis xyz="0 1 0"/>
       <limit effort="0.0" lower="-3.14159" upper="3.14159" velocity="0.0"/>
    </joint>
    <link name="4">
        <inertial>
            <origin xyz="0.4901654006442705 0 5" rpy="0 0 0"/>
            <mass value="1" />
            <inertia ixx="100" ixy="0" ixz="0" iyy="100" iyz="0" izz="100" />
        </inertial>
        <visual>
            <origin xyz="0.4901654006442705 0 5" rpy="0 0 0"/>
            <geometry>
                <box size="0.980330801288541 0.9601547827423139 0.8845920092325746" />
            </geometry>
            <material name="Has sensor">
                <color rgba="0.2 0.66 0.31 1.0"/>
            </material>
        </visual>
        <collision>
            <origin xyz="0.4901654006442705 0 5" rpy="0 0 0"/>
            <geometry>
                <box size="0.980330801288541 0.9601547827423139 0.8845920092325746" />
            </geometry>
        </collision>
    </link>
</robot>