<robot name = "robot">
    <link name="0">
        <inertial>
            <origin xyz="0.8036591950497327 0 5" rpy="0 0 0"/>
            <mass value="1" />
            <inertia ixx="100" ixy="0" ixz="0" iyy="100" iyz="0" izz="100" />
        </inertial>
        <visual>
            <origin xyz="0.8036591950497327 0 5" rpy="0 0 0"/>
            <geometry>
                <box size="0.8036591950497327 0.9076406529671176 0.8167793728116315" />
            </geometry>
            <material name="Has sensor">
                <color rgba="0.2 0.66 0.31 1.0"/>
            </material>
        </visual>
        <collision>
            <origin xyz="0.8036591950497327 0 5" rpy="0 0 0"/>
            <geometry>
                <box size="0.8036591950497327 0.9076406529671176 0.8167793728116315" />
            </geometry>
        </collision>
    </link>
    <joint name="0_1" type="revolute">
       <parent link="0"/>
       <child  link="1"/>
       <origin rpy="0 0 0" xyz="0.8036591950497327 0 5" />
     <axis xyz="0 1 0"/>
       <limit effort="0.0" lower="-3.14159" upper="3.14159" velocity="0.0"/>
    </joint>
    <link name="1">
        <inertial>
            <origin xyz="0.4214302144325006 0 5" rpy="0 0 0"/>
            <mass value="1" />
            <inertia ixx="100" ixy="0" ixz="0" iyy="100" iyz="0" izz="100" />
        </inertial>
        <visual>
            <origin xyz="0.4214302144325006 0 5" rpy="0 0 0"/>
            <geometry>
                <box size="0.8428604288650012 0.7973259130979675 0.7713723722547201" />
            </geometry>
            <material name="Has sensor">
                <color rgba="0.2 0.66 0.31 1.0"/>
            </material>
        </visual>
        <collision>
            <origin xyz="0.4214302144325006 0 5" rpy="0 0 0"/>
            <geometry>
                <box size="0.8428604288650012 0.7973259130979675 0.7713723722547201" />
            </geometry>
        </collision>
    </link>
    <joint name="1_2" type="revolute">
       <parent link="1"/>
       <child  link="2"/>
       <origin rpy="0 0 0" xyz="0.8428604288650012 0 5" />
     <axis xyz="0 1 0"/>
       <limit effort="0.0" lower="-3.14159" upper="3.14159" velocity="0.0"/>
    </joint>
    <link name="2">
        <inertial>
            <origin xyz="0.38145810906747807 0 5" rpy="0 0 0"/>
            <mass value="1" />
            <inertia ixx="100" ixy="0" ixz="0" iyy="100" iyz="0" izz="100" />
        </inertial>
        <visual>
            <origin xyz="0.38145810906747807 0 5" rpy="0 0 0"/>
            <geometry>
                <box size="0.7629162181349561 0.8754775673539389 0.9894469775026211" />
            </geometry>
            <material name="Has sensor">
                <color rgba="0.2 0.66 0.31 1.0"/>
            </material>
        </visual>
        <collision>
            <origin xyz="0.38145810906747807 0 5" rpy="0 0 0"/>
            <geometry>
                <box size="0.7629162181349561 0.8754775673539389 0.9894469775026211" />
            </geometry>
        </collision>
    </link>
    <joint name="2_3" type="revolute">
       <parent link="2"/>
       <child  link="3"/>
       <origin rpy="0 0 0" xyz="0.7629162181349561 0 5" />
     <axis xyz="0 0 1"/>
       <limit effort="0.0" lower="-3.14159" upper="3.14159" velocity="0.0"/>
    </joint>
    <link name="3">
        <inertial>
            <origin xyz="0.4989528646191048 0 5" rpy="0 0 0"/>
            <mass value="1" />
            <inertia ixx="100" ixy="0" ixz="0" iyy="100" iyz="0" izz="100" />
        </inertial>
        <visual>
            <origin xyz="0.4989528646191048 0 5" rpy="0 0 0"/>
            <geometry>
                <box size="0.9979057292382096 0.9166268309334646 0.9872583484862485" />
            </geometry>
            <material name="Has sensor">
                <color rgba="0.2 0.66 0.31 1.0"/>
            </material>
        </visual>
        <collision>
            <origin xyz="0.4989528646191048 0 5" rpy="0 0 0"/>
            <geometry>
                <box size="0.9979057292382096 0.9166268309334646 0.9872583484862485" />
            </geometry>
        </collision>
    </link>
    <joint name="3_4" type="revolute">
       <parent link="3"/>
       <child  link="4"/>
       <origin rpy="0 0 0" xyz="0.9979057292382096 0 5" />
     <axis xyz="0 0 1"/>
       <limit effort="0.0" lower="-3.14159" upper="3.14159" velocity="0.0"/>
    </joint>
    <link name="4">
        <inertial>
            <origin xyz="0.4903047872729562 0 5" rpy="0 0 0"/>
            <mass value="1" />
            <inertia ixx="100" ixy="0" ixz="0" iyy="100" iyz="0" izz="100" />
        </inertial>
        <visual>
            <origin xyz="0.4903047872729562 0 5" rpy="0 0 0"/>
            <geometry>
                <box size="0.9806095745459124 0.9708871686721723 0.7896178541604109" />
            </geometry>
            <material name="No sensor">
                <color rgba="0.44 0.78 0.91 1.0"/>
            </material>
        </visual>
        <collision>
            <origin xyz="0.4903047872729562 0 5" rpy="0 0 0"/>
            <geometry>
                <box size="0.9806095745459124 0.9708871686721723 0.7896178541604109" />
            </geometry>
        </collision>
    </link>
</robot>