<robot name = "robot">
    <link name="0">
        <inertial>
            <origin xyz="0 0 5" rpy="0 0 0"/>
            <mass value="1" />
            <inertia ixx="100" ixy="0" ixz="0" iyy="100" iyz="0" izz="100" />
        </inertial>
        <visual>
            <origin xyz="0 0 5" rpy="0 0 0"/>
            <geometry>
                <box size="0.75 0.75 0.75" />
            </geometry>
            <material name="Has sensor">
                <color rgba="0.2 0.66 0.31 1.0"/>
            </material>
        </visual>
        <collision>
            <origin xyz="0 0 5" rpy="0 0 0"/>
            <geometry>
                <box size="0.75 0.75 0.75" />
            </geometry>
        </collision>
    </link>
    <link name="1">
        <inertial>
            <origin xyz="0.375 0.0 0.0" rpy="0 0 0"/>
            <mass value="1" />
            <inertia ixx="100" ixy="0" ixz="0" iyy="100" iyz="0" izz="100" />
        </inertial>
        <visual>
            <origin xyz="0.375 0.0 0.0" rpy="0 0 0"/>
            <geometry>
                <box size="0.75 0.75 0.75" />
            </geometry>
            <material name="Has sensor">
                <color rgba="0.2 0.66 0.31 1.0"/>
            </material>
        </visual>
        <collision>
            <origin xyz="0.375 0.0 0.0" rpy="0 0 0"/>
            <geometry>
                <box size="0.75 0.75 0.75" />
            </geometry>
        </collision>
    </link>
    <link name="2">
        <inertial>
            <origin xyz="0.375 0.0 0.0" rpy="0 0 0"/>
            <mass value="1" />
            <inertia ixx="100" ixy="0" ixz="0" iyy="100" iyz="0" izz="100" />
        </inertial>
        <visual>
            <origin xyz="0.375 0.0 0.0" rpy="0 0 0"/>
            <geometry>
                <box size="0.75 0.75 0.75" />
            </geometry>
            <material name="Has sensor">
                <color rgba="0.2 0.66 0.31 1.0"/>
            </material>
        </visual>
        <collision>
            <origin xyz="0.375 0.0 0.0" rpy="0 0 0"/>
            <geometry>
                <box size="0.75 0.75 0.75" />
            </geometry>
        </collision>
    </link>
    <link name="3">
        <inertial>
            <origin xyz="0.0 0.0 0.2652563060951815" rpy="0 0 0"/>
            <mass value="1" />
            <inertia ixx="100" ixy="0" ixz="0" iyy="100" iyz="0" izz="100" />
        </inertial>
        <visual>
            <origin xyz="0.0 0.0 0.2652563060951815" rpy="0 0 0"/>
            <geometry>
                <box size="0.39290131252010707 0.6590613934307896 0.530512612190363" />
            </geometry>
            <material name="No sensor">
                <color rgba="0.44 0.78 0.91 1.0"/>
            </material>
        </visual>
        <collision>
            <origin xyz="0.0 0.0 0.2652563060951815" rpy="0 0 0"/>
            <geometry>
                <box size="0.39290131252010707 0.6590613934307896 0.530512612190363" />
            </geometry>
        </collision>
    </link>
    <link name="4">
        <inertial>
            <origin xyz="0.0 0.0 -0.31006121397771885" rpy="0 0 0"/>
            <mass value="1" />
            <inertia ixx="100" ixy="0" ixz="0" iyy="100" iyz="0" izz="100" />
        </inertial>
        <visual>
            <origin xyz="0.0 0.0 -0.31006121397771885" rpy="0 0 0"/>
            <geometry>
                <box size="0.5211962470650614 0.32478025071457917 0.6201224279554377" />
            </geometry>
            <material name="No sensor">
                <color rgba="0.44 0.78 0.91 1.0"/>
            </material>
        </visual>
        <collision>
            <origin xyz="0.0 0.0 -0.31006121397771885" rpy="0 0 0"/>
            <geometry>
                <box size="0.5211962470650614 0.32478025071457917 0.6201224279554377" />
            </geometry>
        </collision>
    </link>
    <link name="5">
        <inertial>
            <origin xyz="0.0 0.3461714427727924 0.0" rpy="0 0 0"/>
            <mass value="1" />
            <inertia ixx="100" ixy="0" ixz="0" iyy="100" iyz="0" izz="100" />
        </inertial>
        <visual>
            <origin xyz="0.0 0.3461714427727924 0.0" rpy="0 0 0"/>
            <geometry>
                <box size="0.5028057829258865 0.6923428855455848 0.7067552392749152" />
            </geometry>
            <material name="No sensor">
                <color rgba="0.44 0.78 0.91 1.0"/>
            </material>
        </visual>
        <collision>
            <origin xyz="0.0 0.3461714427727924 0.0" rpy="0 0 0"/>
            <geometry>
                <box size="0.5028057829258865 0.6923428855455848 0.7067552392749152" />
            </geometry>
        </collision>
    </link>
    <link name="6">
        <inertial>
            <origin xyz="0.0 0.0 0.15827440729892042" rpy="0 0 0"/>
            <mass value="1" />
            <inertia ixx="100" ixy="0" ixz="0" iyy="100" iyz="0" izz="100" />
        </inertial>
        <visual>
            <origin xyz="0.0 0.0 0.15827440729892042" rpy="0 0 0"/>
            <geometry>
                <box size="0.3303488403925323 0.12445416462993363 0.31654881459784084" />
            </geometry>
            <material name="Has sensor">
                <color rgba="0.2 0.66 0.31 1.0"/>
            </material>
        </visual>
        <collision>
            <origin xyz="0.0 0.0 0.15827440729892042" rpy="0 0 0"/>
            <geometry>
                <box size="0.3303488403925323 0.12445416462993363 0.31654881459784084" />
            </geometry>
        </collision>
    </link>
    <link name="7">
        <inertial>
            <origin xyz="0.0 0.0 -0.367172202130295" rpy="0 0 0"/>
            <mass value="1" />
            <inertia ixx="100" ixy="0" ixz="0" iyy="100" iyz="0" izz="100" />
        </inertial>
        <visual>
            <origin xyz="0.0 0.0 -0.367172202130295" rpy="0 0 0"/>
            <geometry>
                <box size="0.29510116772094874 0.3914006487718668 0.73434440426059" />
            </geometry>
            <material name="No sensor">
                <color rgba="0.44 0.78 0.91 1.0"/>
            </material>
        </visual>
        <collision>
            <origin xyz="0.0 0.0 -0.367172202130295" rpy="0 0 0"/>
            <geometry>
                <box size="0.29510116772094874 0.3914006487718668 0.73434440426059" />
            </geometry>
        </collision>
    </link>
    <link name="8">
        <inertial>
            <origin xyz="0.0 -0.23273666028538437 0.0" rpy="0 0 0"/>
            <mass value="1" />
            <inertia ixx="100" ixy="0" ixz="0" iyy="100" iyz="0" izz="100" />
        </inertial>
        <visual>
            <origin xyz="0.0 -0.23273666028538437 0.0" rpy="0 0 0"/>
            <geometry>
                <box size="0.1991209736660626 0.46547332057076873 0.3919479104096162" />
            </geometry>
            <material name="No sensor">
                <color rgba="0.44 0.78 0.91 1.0"/>
            </material>
        </visual>
        <collision>
            <origin xyz="0.0 -0.23273666028538437 0.0" rpy="0 0 0"/>
            <geometry>
                <box size="0.1991209736660626 0.46547332057076873 0.3919479104096162" />
            </geometry>
        </collision>
    </link>
    <link name="9">
        <inertial>
            <origin xyz="0.0 0.0 -0.08477765885196142" rpy="0 0 0"/>
            <mass value="1" />
            <inertia ixx="100" ixy="0" ixz="0" iyy="100" iyz="0" izz="100" />
        </inertial>
        <visual>
            <origin xyz="0.0 0.0 -0.08477765885196142" rpy="0 0 0"/>
            <geometry>
                <box size="0.27420023861450893 0.20072962972278502 0.16955531770392285" />
            </geometry>
            <material name="No sensor">
                <color rgba="0.44 0.78 0.91 1.0"/>
            </material>
        </visual>
        <collision>
            <origin xyz="0.0 0.0 -0.08477765885196142" rpy="0 0 0"/>
            <geometry>
                <box size="0.27420023861450893 0.20072962972278502 0.16955531770392285" />
            </geometry>
        </collision>
    </link>
    <joint name="0_1" type="revolute">
       <parent link="0"/>
       <child  link="1"/>
       <origin rpy="0 0 0" xyz="0.375 0.0 5.0" />
     <axis xyz="0 0 1"/>
       <limit effort="0.0" lower="-3.14159" upper="3.14159" velocity="0.0"/>
    </joint>
    <joint name="1_2" type="revolute">
       <parent link="1"/>
       <child  link="2"/>
       <origin rpy="0 0 0" xyz="0.75 0.0 0.0" />
     <axis xyz="0 1 0"/>
       <limit effort="0.0" lower="-3.14159" upper="3.14159" velocity="0.0"/>
    </joint>
    <joint name="0_3" type="revolute">
       <parent link="0"/>
       <child  link="3"/>
       <origin rpy="0 0 0" xyz="0.0 0.0 5.375" />
     <axis xyz="1 0 0"/>
       <limit effort="0.0" lower="-3.14159" upper="3.14159" velocity="0.0"/>
    </joint>
    <joint name="0_4" type="revolute">
       <parent link="0"/>
       <child  link="4"/>
       <origin rpy="0 0 0" xyz="0.0 0.0 4.625" />
     <axis xyz="1 0 0"/>
       <limit effort="0.0" lower="-3.14159" upper="3.14159" velocity="0.0"/>
    </joint>
    <joint name="2_5" type="revolute">
       <parent link="2"/>
       <child  link="5"/>
       <origin rpy="0 0 0" xyz="0.375 0.375 0.0" />
     <axis xyz="1 0 0"/>
       <limit effort="0.0" lower="-3.14159" upper="3.14159" velocity="0.0"/>
    </joint>
    <joint name="5_6" type="revolute">
       <parent link="5"/>
       <child  link="6"/>
       <origin rpy="0 0 0" xyz="0.0 0.3461714427727924 0.3533776196374576" />
     <axis xyz="1 0 0"/>
       <limit effort="0.0" lower="-3.14159" upper="3.14159" velocity="0.0"/>
    </joint>
    <joint name="2_7" type="revolute">
       <parent link="2"/>
       <child  link="7"/>
       <origin rpy="0 0 0" xyz="0.375 0.0 -0.375" />
     <axis xyz="1 0 0"/>
       <limit effort="0.0" lower="-3.14159" upper="3.14159" velocity="0.0"/>
    </joint>
    <joint name="7_8" type="revolute">
       <parent link="7"/>
       <child  link="8"/>
       <origin rpy="0 0 0" xyz="0.0 -0.1957003243859334 -0.367172202130295" />
     <axis xyz="1 0 0"/>
       <limit effort="0.0" lower="-3.14159" upper="3.14159" velocity="0.0"/>
    </joint>
    <joint name="8_9" type="revolute">
       <parent link="8"/>
       <child  link="9"/>
       <origin rpy="0 0 0" xyz="0.0 -0.23273666028538437 -0.1959739552048081" />
     <axis xyz="1 0 0"/>
       <limit effort="0.0" lower="-3.14159" upper="3.14159" velocity="0.0"/>
    </joint>
</robot>